Workbook

Sheet TAM summary
A1: TAM summary
A2: Top-down TAM by bucket — FY24 through FY26, with OBBA reconciliation breakout
A3: All figures in USD thousands ($K)
A4: # | B4: Bucket | C4: FY24 Actual | D4: FY25 Enacted | E4: FY26 Request | F4: FY26 OBBA | G4: FY26 Total | H4: % of Full TAM | I4: % of In-Service
A5: 1 | B5: New Construction | C5: 28427000 | D5: 38453000 | E5: 19822000 | F5: 26507000 | G5: 46326000 | H5: =G5/G13 -> 0.61822784 | I5: —
A6: 2 | B6: Scheduled Depot Maintenance & Repair | C6: 13271718 | D6: 12909097 | E6: 13617194 | F6: 0 | G6: 13617194 | H6: =G6/G13 -> 0.18172362 | I6: =G6/G12 -> 0.47600019
A7: 3 | B7: Continuous / Intermediate / Emergent | C7: 2083638 | D7: 2155459 | E7: 2234715 | F7: 0 | G7: 2234715 | H7: =G7/G13 -> 0.029822627 | I7: =G7/G12 -> 0.078116297
A8: 4 | B8: Modernization & Alteration Installation | C8: 5505882 | D8: 5994559 | E8: 6624111 | F8: 0 | G8: 6624111 | H8: =G8/G13 -> 0.088399815 | I8: =G8/G12 -> 0.23155124
A9: 5 | B9: Major Life-Cycle Events (RCOH/SLEP/MMA) | C9: 210612 | D9: 1661363 | E9: 2492740 | F9: 0 | G9: 2492740 | H9: =G9/G13 -> 0.033266012 | I9: =G9/G12 -> 0.087135772
A10: 6 | B10: Sustainment Engineering / Planning | C10: 3192575 | D10: 3143211 | E10: 3411003 | F10: 0 | G10: 3411003 | H10: =G10/G13 -> 0.045520378 | I10: =G10/G12 -> 0.11923441
A11: 7 | B11: Availability Support / Port Services | C11: 254506 | D11: 226912 | E11: 227776 | F11: 0 | G11: 227776 | H11: =G11/G13 -> 0.003039707 | I11: =G11/G12 -> 0.007962097
B12: In-Service (Buckets 2–7) | C12: =SUM(C6:C11) -> 24518931 | D12: =SUM(D6:D11) -> 26090601 | E12: =SUM(E6:E11) -> 28607539 | F12: =SUM(F6:F11) -> 0 | G12: =SUM(G6:G11) -> 28607539
B13: Full TAM | C13: =SUM(C5:C11) -> 52945931 | D13: =SUM(D5:D11) -> 64543601 | E13: =SUM(E5:E11) -> 48429539 | F13: =SUM(F5:F11) -> 26507000 | G13: =SUM(G5:G11) -> 74933539

Sheet By vessel class
A1: By vessel class
A2: FY26 spending by vessel class and bucket — budget book data only, no analyst estimates
A3: All figures in USD thousands ($K), FY26
A4: Vessel Class | B4: B1 Request | C4: B1 OBBA | D4: B1 Total | E4: B2 | F4: B3 | G4: B4 | H4: B5 | I4: B6 | J4: B7 | K4: Row Total
A5: Navy Submarines
A6: SSBN (Columbia) | B6: 8994594 | C6: 1925892 | D6: 10920486 | E6: N/A | F6: N/A | G6: N/A | H6: N/A | I6: N/A | J6: N/A | K6: =SUM(D6:J6) -> 10920486
A7: SSN (Virginia) | B7: 4760225 | C7: 6317804 | D7: 11078029 | E7: N/A | F7: N/A | G7: N/A | H7: N/A | I7: N/A | J7: N/A | K7: =SUM(D7:J7) -> 11078029
A8: SSN/SSBN (in-service) | B8: 0 | C8: 0 | D8: 0 | E8: 1566819 | F8: N/A | G8: 766254 | H8: 0 | I8: 0 | J8: N/A | K8: =SUM(D8:J8) -> 2333073
A9: Navy Surface
A10: CVN (Nimitz/Ford) | B10: 3281673 | C10: 0 | D10: 3281673 | E10: 784000 | F10: N/A | G10: 0 | H10: 2274311 | I10: 86561 | J10: N/A | K10: =SUM(D10:J10) -> 6426545
A11: DDG-51 | B11: 10773 | C11: 5400000 | D11: 5410773 | E11: 749000 | F11: N/A | G11: 997485 | H11: 0 | I11: 0 | J11: N/A | K11: =SUM(D11:J11) -> 7157258
A12: DDG-1000 | B12: 52358 | C12: 0 | D12: 52358 | E12: 0 | F12: N/A | G12: 115267 | H12: 0 | I12: 209225 | J12: N/A | K12: =SUM(D12:J12) -> 376850
A13: CG (Ticonderoga) | B13: 0 | C13: 0 | D13: 0 | E13: 0 | F13: N/A | G13: 0 | H13: 0 | I13: 0 | J13: N/A | K13: =SUM(D13:J13) -> 0
A14: FFG-62 | B14: 0 | C14: 0 | D14: 0 | E14: 0 | F14: N/A | G14: 0 | H14: 0 | I14: 0 | J14: N/A | K14: =SUM(D14:J14) -> 0
A15: LCS | B15: 0 | C15: 0 | D15: 0 | E15: 492493 | F15: N/A | G15: 374321 | H15: 0 | I15: 0 | J15: N/A | K15: =SUM(D15:J15) -> 866814
A16: Navy Amphibious
A17: Amphibious (combined) | B17: 0 | C17: 0 | D17: 0 | E17: 624506 | F17: N/A | G17: 0 | H17: 0 | I17: 0 | J17: N/A | K17: =SUM(D17:J17) -> 624506
A18: LPD Flight II | B18: 0 | C18: 2600000 | D18: 2600000 | E18: N/A | F18: N/A | G18: 125542 | H18: 0 | I18: 0 | J18: N/A | K18: =SUM(D18:J18) -> 2725542
A19: LHA | B19: 0 | C19: 3895000 | D19: 3895000 | E19: N/A | F19: N/A | G19: 123384 | H19: 0 | I19: 0 | J19: N/A | K19: =SUM(D19:J19) -> 4018384
A20: LSD | B20: 0 | C20: 0 | D20: 0 | E20: N/A | F20: N/A | G20: 4079 | H20: 0 | I20: 0 | J20: N/A | K20: =SUM(D20:J20) -> 4079
A21: LSM | B21: 0 | C21: 1963941 | D21: 1963941 | E21: 0 | F21: N/A | G21: 0 | H21: 0 | I21: 0 | J21: N/A | K21: =SUM(D21:J21) -> 1963941
A22: Navy Auxiliaries
A23: T-AO (John Lewis) | B23: 8346 | C23: 1853359 | D23: 1861705 | E23: 0 | F23: N/A | G23: 0 | H23: 0 | I23: 0 | J23: N/A | K23: =SUM(D23:J23) -> 1861705
A24: T-AGOS | B24: 612205 | C24: 0 | D24: 612205 | E24: 0 | F24: N/A | G24: 0 | H24: 0 | I24: 0 | J24: N/A | K24: =SUM(D24:J24) -> 612205
A25: SSC/LCAC | B25: 0 | C25: 239095 | D25: 239095 | E25: 0 | F25: N/A | G25: 20321 | H25: 37883 | I25: 0 | J25: N/A | K25: =SUM(D25:J25) -> 297299
A26: LCU 1700 | B26: 0 | C26: 295000 | D26: 295000 | E26: 0 | F26: N/A | G26: 0 | H26: 0 | I26: 0 | J26: N/A | K26: =SUM(D26:J26) -> 295000
A27: Sealift (Strategic + Used) | B27: 45000 | C27: 700000 | D27: 745000 | E27: 0 | F27: N/A | G27: 0 | H27: 0 | I27: 0 | J27: N/A | K27: =SUM(D27:J27) -> 745000
A28: LCC | B28: 0 | C28: 0 | D28: 0 | E28: 0 | F28: N/A | G28: 0 | H28: 19276 | I28: 0 | J28: N/A | K28: =SUM(D28:J28) -> 19276
A29: ESB/ESD | B29: 0 | C29: 0 | D29: 0 | E29: 0 | F29: N/A | G29: 0 | H29: 0 | I29: 0 | J29: N/A | K29: =SUM(D29:J29) -> 0
A30: MSC Fleet | B30: 0 | C30: 0 | D30: 0 | E30: 1584000 | F30: N/A | G30: 0 | H30: 0 | I30: 0 | J30: N/A | K30: =SUM(D30:J30) -> 1584000
A31: Service Craft / APL | B31: 34602 | C31: 0 | D31: 34602 | E31: 0 | F31: N/A | G31: 0 | H31: 0 | I31: 0 | J31: N/A | K31: =SUM(D31:J31) -> 34602
A32: Coast Guard
A33: CG: OPC (Heritage) | B33: 812400 | C33: 0 | D33: 812400 | E33: 0 | F33: N/A | G33: 0 | H33: 0 | I33: 0 | J33: N/A | K33: =SUM(D33:J33) -> 812400
A34: CG: FRC (Sentinel) | B34: 216000 | C34: 0 | D34: 216000 | E34: 0 | F34: N/A | G34: 0 | H34: 0 | I34: 0 | J34: N/A | K34: =SUM(D34:J34) -> 216000
A35: CG: PSC / WCC / Icebreaker | B35: 228000 | C35: 0 | D35: 228000 | E35: 0 | F35: N/A | G35: 0 | H35: 0 | I35: 0 | J35: N/A | K35: =SUM(D35:J35) -> 228000
A36: CG: WMEC-270 | B36: 0 | C36: 0 | D36: 0 | E36: N/A | F36: N/A | G36: 0 | H36: 76000 | I36: 0 | J36: N/A | K36: =SUM(D36:J36) -> 76000
A37: CG: WLM-175 | B37: 0 | C37: 0 | D37: 0 | E37: N/A | F37: N/A | G37: 0 | H37: 15000 | I37: 0 | J37: N/A | K37: =SUM(D37:J37) -> 15000
A38: CG: MLB-47 | B38: 0 | C38: 0 | D38: 0 | E38: N/A | F38: N/A | G38: 0 | H38: 45000 | I38: 0 | J38: N/A | K38: =SUM(D38:J38) -> 45000
A39: CG: Healy / WMSL | B39: 0 | C39: 0 | D39: 0 | E39: N/A | F39: N/A | G39: 0 | H39: 16000 | I39: 0 | J39: N/A | K39: =SUM(D39:J39) -> 16000
A40: CG: RB-M | B40: 0 | C40: 0 | D40: 0 | E40: N/A | F40: N/A | G40: 0 | H40: 9270 | I40: 0 | J40: N/A | K40: =SUM(D40:J40) -> 9270
...

Sheet All line items
A1: All line items
A2: Master list of all extracted line items across all seven buckets
A3: All figures in USD thousands ($K)
A4: Source | B4: Line Item | C4: Vessel Class | D4: Bucket | E4: Performer | F4: FY24 | G4: FY25 | H4: FY26 Total | I4: Confidence | J4: Notes
A5: SCN L1+L2 | B5: Columbia Class (ship + AP) | C5: SSBN (Columbia) | D5: 1 | E5: GD Electric Boat / HII NNS | F5: 0 | G5: 9580774 | H5: 10920486 | I5: High | J5: FY24 zero = no new TOA
A6: SCN L8+L9 | B6: Virginia Class (ship + AP) | C6: SSN (Virginia) | D6: 1 | E6: GD Electric Boat / HII NNS | F6: 10656927 | G6: 13320211 | H6: 11078029 | I6: High | J6: FY26: $4.8B Req + $6.3B OBBA
A7: SCN L5+L6+L7 | B7: CVN-81 Carrier Replacement | C7: CVN (Ford) | D7: 1 | E7: HII Newport News | F7: 2529513 | G7: 2034054 | H7: 3281673 | I7: High | J7: CVN-80 SFF + CVN-81 ramp
A8: SCN L13+L14 | B8: DDG-51 (ship + AP) | C8: DDG-51 (Flt III) | D8: 1 | E8: HII Ingalls / GD BIW | F8: 6366431 | G8: 8268628 | H8: 5410773 | I8: High | J8: FY26: $11K Req + $5.4B OBBA
A9: SCN L12 | B9: DDG-1000 Completion | C9: DDG-1000 | D9: 1 | E9: GD Bath Iron Works | F9: 392892 | G9: 61100 | H9: 52358 | I9: High | J9: Completion/CPS only
A10: SCN L16 | B10: FFG-62 Constellation | C10: FFG-62 | D10: 1 | E10: Marinette Marine | F10: 2183861 | G10: 633200 | H10: 0 | I10: High | J10: No FY26 funding
A11: SCN L15 | B11: LCS Completion | C11: LCS | D11: 1 | E11: Austal USA / LM | F11: 23000 | G11: 48000 | H11: 0 | I11: High | J11: Program ending
A12: SCN L19+L20+L21 | B12: LPD Flight II | C12: LPD | D12: 1 | E12: HII Ingalls | F12: 516520 | G12: 1581121 | H12: 2600000 | I12: High | J12: FY26 entirely OBBA
A13: SCN L24+L25 | B13: LHA Replacement | C13: LHA | D13: 1 | E13: HII Ingalls | F13: 1830149 | G13: 176515 | H13: 3895000 | I13: High | J13: FY26 entirely OBBA
A14: SCN L27 | B14: Medium Landing Ship | C14: LSM | D14: 1 | E14: TBD | F14: 0 | G14: 29668 | H14: 1963941 | I14: High | J14: 9-ship block buy in OBBA
A15: SCN L31 | B15: T-AO Fleet Oiler | C15: T-AO | D15: 1 | E15: GD NASSCO | F15: 938315 | G15: 227154 | H15: 1861705 | I15: High | J15: FY26: $8K Req + $1.85B OBBA
A16: SCN L34 | B16: TAGOS Surtass Ships | C16: T-AGOS | D16: 1 | E16: TBD | F16: 513466 | G16: 0 | H16: 612205 | I16: High
A17: SCN L35 | B17: ATS (Towing/Salvage) | C17: ATS | D17: 1 | E17: TBD | F17: 22959 | G17: 82587 | H17: 0 | I17: High | J17: Completion only
A18: SCN L37 | B18: Oceanographic Ships | C18: T-AGS | D18: 1 | E18: TBD | F18: 0 | G18: 18000 | H18: 0 | I18: High | J18: Completion only
A19: SCN L39 | B19: LCU 1700 | C19: LCU | D19: 1 | E19: TBD | F19: 62532 | G19: 0 | H19: 295000 | I19: High | J19: FY26 OBBA: 9 craft
A20: SCN L40 | B20: Strategic Sealift | C20: Sealift | D20: 1 | E20: TBD | F20: 0 | G20: 0 | H20: 600000 | I20: High | J20: FY26 OBBA
A21: SCN L42 | B21: Ship to Shore Connector | C21: SSC | D21: 1 | E21: Textron | F21: 628600 | G21: 528039 | H21: 239095 | I21: High | J21: LCAC replacement
A22: SCN L43 | B22: Service Craft | C22: Various | D22: 1 | E22: Various | F22: 93815 | G22: 41426 | H22: 34602 | I22: High
A23: SCN L44 | B23: Aux Personnel Lighter | C23: APL | D23: 1 | E23: TBD | F23: 72000 | G23: 76168 | H23: 0 | I23: High
A24: SCN L48 | B24: Auxiliary Vessels (Used Sealift) | C24: Sealift | D24: 1 | E24: Various | F24: 142008 | G24: 204939 | H24: 145000 | I24: High | J24: Used vessel acquisition
A25: SCN L41 | B25: Outfitting (all newbuild) | C25: Multi-class | D25: 1 | E25: Various | F25: 512019 | G25: 585967 | H25: 887295 | I25: High | J25: Post-delivery outfitting
A26: SCN L49 | B26: PY Completion (Bucket 1 share) | C26: Multi-class | D26: 1 | E26: Various | F26: 0 | G26: 0 | H26: 1192266 | I26: High | J26: CTC minus RCOH/LCAC
A27: USCG PC&I | B27: Offshore Patrol Cutter | C27: CG: OPC | D27: 1 | E27: Eastern Shipbuilding | F27: 579000 | G27: 579000 | H27: 812400 | I27: High | J27: OPCs #8-9; LLTM #10-11
A28: USCG PC&I | B28: Fast Response Cutter | C28: CG: FRC | D28: 1 | E28: Bollinger | F28: 220000 | G28: 220000 | H28: 216000 | I28: High | J28: FRCs #62-64
A29: USCG PC&I | B29: Polar Security Cutter | C29: CG: PSC | D29: 1 | E29: Bollinger | F29: 0 | G29: 0 | H29: 130000 | I29: High | J29: PSC #1 construction
A30: USCG PC&I | B30: Waterways Commerce Cutter | C30: CG: WCC | D30: 1 | E30: TBD | F30: 1000 | G30: 1000 | H30: 98000 | I30: High
A31: USCG PC&I | B31: NSC Completion | C31: CG: NSC | D31: 1 | E31: HII Ingalls | F31: 17100 | G31: 17100 | H31: 0 | I31: High | J31: Complete after FY25
A32: USCG PC&I | B32: Commercial Polar Icebreaker | C32: CG: Icebreaker | D32: 1 | E32: Commercial | F32: 125000 | G32: 125000 | H32: 0 | I32: High | J32: CGC Storis acquisition
A33: USCG PC&I | B33: Great Lakes Icebreaker | C33: CG: Icebreaker | D33: 1 | E33: TBD | F33: 20000 | G33: 20000 | H33: 0 | I33: High
A34: OMN 1B4B | B34: Ship Modernization Program (SMP) | C34: Multi-class | D34: 2 | E34: Mixed | F34: 1203816 | G34: 869253 | H34: 1197180 | I34: High
A35: OMN 1B4B | B35: NME / 2-Hatch Ships | C35: Multi-class | D35: 2 | E35: Mixed | F35: 1197197 | G35: 1306411 | H35: 1341155 | I35: High
A36: OMN 1B4B | B36: NME / 4-Hatch Ships | C36: Multi-class | D36: 2 | E36: Mixed | F36: 1247653 | G36: 1290155 | H36: 1289894 | I36: High
A37: OMN 1B4B | B37: NME / Submarine Availability | C37: SSN/SSBN | D37: 2 | E37: Public Yard | F37: 871537 | G37: 896253 | H37: 924629 | I37: High | J37: Primarily NNSY/PHNSY
A38: OMN 1B4B | B38: NME / Industrial Base | C38: Multi-class | D38: 2 | E38: Mixed | F38: 1245621 | G38: 1270256 | H38: 1267865 | I38: High
A39: OMN 1B4B | B39: NME / NAVPLAN | C39: Multi-class | D39: 2 | E39: Mixed | F39: 1134835 | G39: 1139556 | H39: 1134328 | I39: High
A40: OMN 1B4B | B40: NME / SSN-to-Repair | C40: SSN/SSBN | D40: 2 | E40: Public Yard | F40: 630555 | G40: 639229 | H40: 642190 | I40: High | J40: Public yard sub repair
...

Sheet PB-61 detail
A1: PB-61 detail
A2: PB-61 Depot Maintenance Summary — per-class detail from OMN Vol2
A3: All figures in USD thousands ($K)
A5: OMN — Ship Maint (Bucket 2)
A6: Weapon System | B6: FY24 Total | C6: FY25 Funded | D6: FY25 Required | E6: FY25 % | F6: FY26 Funded | G6: FY26 Required | H6: FY26 %
A7: CV-CVN | B7: 1796346 | C7: 2748996 | D7: 2897547 | E7: 0.95 | F7: 2720122 | G7: 3030280 | H7: 0.9
A8: CV-CVN (SRB) | B8: 278 | C8: 312 | D8: 312 | E8: 1 | F8: 312 | G8: 323 | H8: 0.97
A9: CVN | B9: 0 | C9: 0 | D9: 0 | E9: N/A | F9: 17657 | G9: 18054 | H9: 0.98
A10: DDG | B10: 732057 | C10: 563674 | D10: 595584 | E10: 0.95 | F10: 525288 | G10: 568246 | H10: 0.92
A11: DDG-1000 | B11: 0 | C11: 0 | D11: 0 | E11: N/A | F11: 6174 | G11: 7358 | H11: 0.84
A12: SSN-MTS-SSGN | B12: 2524018 | C12: 2635557 | D12: 2765819 | E12: 0.95 | F12: 2431863 | G12: 2531177 | H12: 0.96
A13: SSN-SSGN | B13: 1964943 | C13: 1633867 | D13: 1758233 | E13: 0.93 | F13: 1410798 | G13: 1598434 | H13: 0.88
A14: SSN | B14: 94867 | C14: 126352 | D14: 126352 | E14: 1 | F14: 584293 | G14: 592946 | H14: 0.99
A15: SSBN | B15: 424396 | C15: 276204 | D15: 276424 | E15: 1 | F15: 301080 | G15: 307425 | H15: 0.98
A16: SSGN | B16: 0 | C16: 0 | D16: 0 | E16: N/A | F16: 67781 | G16: 67846 | H16: 1
A17: AMPHIBS | B17: 518125 | C17: 474175 | D17: 499230 | E17: 0.95 | F17: 180719 | G17: 223014 | H17: 0.81
A18: LCS | B18: 241434 | C18: 225747 | D18: 237189 | E18: 0.95 | F18: 230789 | G18: 346046 | H18: 0.67
A19: LPD | B19: 0 | C19: 0 | D19: 0 | E19: N/A | F19: 105286 | G19: 105354 | H19: 1
A20: LHA | B20: 0 | C20: 0 | D20: 0 | E20: N/A | F20: 29116 | G20: 30946 | H20: 0.94
A21: LHD | B21: 0 | C21: 0 | D21: 0 | E21: N/A | F21: 36577 | G21: 37210 | H21: 0.98
A22: LSD | B22: 0 | C22: 0 | D22: 0 | E22: N/A | F22: 73346 | G22: 97543 | H22: 0.75
A23: CG | B23: 106091 | C23: 50328 | D23: 51680 | E23: 0.97 | F23: 40292 | G23: 42503 | H23: 0.95
A24: ESB | B24: 6850 | C24: 20241 | D24: 20629 | E24: 0.98 | F24: 19655 | G24: 22134 | H24: 0.89
A25: LCC | B25: 5496 | C25: 517 | D25: 517 | E25: 1 | F25: 3899 | G25: 57265 | H25: 0.07
A26: AGF-LCC | B26: 15372 | C26: 65480 | D26: 65674 | E26: 1 | F26: 2762 | G26: 3093 | H26: 0.89
A27: MCM-MHC | B27: 55837 | C27: 46252 | D27: 47028 | E27: 0.98 | F27: 10813 | G27: 13189 | H27: 0.82
A28: SOH | B28: 13902 | C28: 27805 | D28: 27805 | E28: 1 | F28: 27382 | G28: 29120 | H28: 0.94
A29: ARDM-AS | B29: 1903 | C29: 89284 | D29: 89284 | E29: 1 | F29: 24967 | G29: 24967 | H29: 1
A30: AS-ARDM | B30: 17244 | C30: 23306 | D30: 23632 | E30: 0.99 | F30: 8400 | G30: 8751 | H30: 0.96
A32: OMN — Continuous Maintenance (Bucket 3)
A33: Weapon System | B33: FY24 Total | C33: FY25 Funded | D33: FY25 Required | E33: FY25 % | F33: FY26 Funded | G33: FY26 Required | H33: FY26 %
A34: DDG | B34: 106432 | C34: 100690 | D34: 100690 | E34: 1 | F34: 123497 | G34: 123497 | H34: 1
A35: LCS | B35: 60812 | C35: 69375 | D35: 69375 | E35: 1 | F35: 69759 | G35: 69759 | H35: 1
A36: CG | B36: 3066 | C36: 5200 | D36: 5200 | E36: 1 | F36: 5969 | G36: 5969 | H36: 1
A37: DDG-1000 | B37: 0 | C37: 3950 | D37: 3950 | E37: 1 | F37: 7645 | G37: 7645 | H37: 1
A38: LCAC | B38: 9219 | C38: 7720 | D38: 7720 | E38: 1 | F38: 7952 | G38: 7952 | H38: 1
A39: AMPHIBS | B39: 15037 | C39: 17188 | D39: 17188 | E39: 1 | F39: 0 | G39: 0 | H39: N/A
A40: MINESWEEPERS | B40: 370 | C40: 1620 | D40: 1620 | E40: 1 | F40: 1068 | G40: 1068 | H40: 1
A41: Other | B41: 89976 | C41: 155923 | D41: 155923 | E41: 1 | F41: 127665 | G41: 127665 | H41: 1
A43: OMN — Other Depot Maintenance
...

Sheet Sources and methodology
A1: Sources and methodology
A2: Data sources, confidence levels, methodology notes, and reconciliation checks
A4: Source Files
A5: SCN Justification Book (PB-27) | B5: Bucket 1 new construction line items and OBBA detail
A6: OMN Vol 2 (PB-61) | B6: Buckets 2-3 depot maintenance and continuous maintenance by weapon system
A7: OPN Justification Book (PB-28) | B7: Bucket 4 modernization equipment and Bucket 2 material support
A8: USCG Capital Investment Plan | B8: Coast Guard PC&I acquisition and SLEP programs
A9: USCG O&S Budget Justification | B9: Coast Guard operations and support allocated to vessel maintenance
A10: OPN BA8 Initial Spares | B10: Bucket 6 war reserve and initial spares (BLI 9020)
A11: NAVSEA HQ / SUPSHIP data | B11: Bucket 6 sustainment engineering and planning overhead
A13: Confidence Levels
A14: High | B14: Direct budget line item with no estimation or allocation required
A15: Medium | B15: Derived from budget data with minor analyst allocation (e.g., percentage split)
A16: Low | B16: Analyst estimate based on historical patterns, indirect evidence, or proxy data
A18: Key Methodology Notes
A19: 1. All figures are in USD thousands ($K) unless otherwise noted.
A20: 2. FY26 OBBA (Off-Budget Baseline Adjustment) reflects supplemental shipbuilding funding in the NDAA.
A21: 3. Coast Guard O&S is split 60/40 between Bucket 2 (depot) and Bucket 3 (continuous) based on analyst estimate.
A22: 4. OPN lines with partial vessel share (e.g., 80%, 95%) reflect analyst allocation of ship-applicable portion.
A23: 5. MSC M&R ($1.584B) is a new FY26 transfer from Navy Working Capital Fund and was not in FY24-25 baselines.
A24: 6. PY Completion (prior-year) is split between Bucket 1 (newbuild) and Bucket 5 (RCOH/SLEP) based on program detail.
A25: 7. Residual NME rounding line in Bucket 2 is a balancing entry to match the SAG-level control total.
A26: 8. Bucket 7 (Availability Support) captures port services, berthing, and facility support not included in depot events.
A28: Annotation Key
A29: N/A | B29: Budget source does not break this data out by vessel class for this bucket
A30: — (dash) | B30: Genuine zero value; the number format renders 0 as a dash
A31: Blue text | B31: Hardcoded numeric input from budget documents
A32: Green text | B32: Cross-tab formula linking to another worksheet
A33: Gray text | B33: Source references, notes, or analyst annotations
A35: Reconciliation Checks
A36: Bucket | B36: Tab 1 Value | C36: Tab 2 Column Total | D36: Delta | E36: Status
A37: Bucket 1 (New Construction) | B37: ='TAM summary'!G5 -> 46326000 | C37: ='By vessel class'!D46 -> 46325828 | D37: =B37-C37 -> 172 | E37: =IF(ABS(D37)<1,"PASS","FAIL") -> FAIL
A38: Bucket 2 (Scheduled Depot Maint) | B38: ='TAM summary'!G6 -> 13617194 | C38: ='By vessel class'!E46 -> #VALUE! | D38: =B38-C38 -> #VALUE! | E38: =IF(ABS(D38)<1,"PASS","FAIL") -> #VALUE!
A39: Bucket 3 (Continuous/Intermediate) | B39: ='TAM summary'!G7 -> 2234715 | C39: ='By vessel class'!F46 -> #VALUE! | D39: =B39-C39 -> #VALUE! | E39: =IF(ABS(D39)<1,"PASS","FAIL") -> #VALUE!
A40: Bucket 4 (Modernization) | B40: ='TAM summary'!G8 -> 6624111 | C40: ='By vessel class'!G46 -> #VALUE! | D40: =B40-C40 -> #VALUE! | E40: =IF(ABS(D40)<1,"PASS","FAIL") -> #VALUE!
A41: Bucket 5 (Major Life-Cycle) | B41: ='TAM summary'!G9 -> 2492740 | C41: ='By vessel class'!H46 -> #VALUE! | D41: =B41-C41 -> #VALUE! | E41: =IF(ABS(D41)<1,"PASS","FAIL") -> #VALUE!
A42: Bucket 6 (Sustainment Eng) | B42: ='TAM summary'!G10 -> 3411003 | C42: ='By vessel class'!I46 -> #VALUE! | D42: =B42-C42 -> #VALUE! | E42: =IF(ABS(D42)<1,"PASS","FAIL") -> #VALUE!
A43: Bucket 7 (Availability Support) | B43: ='TAM summary'!G11 -> 227776 | C43: ='By vessel class'!J46 -> #VALUE! | D43: =B43-C43 -> #VALUE! | E43: =IF(ABS(D43)<1,"PASS","FAIL") -> #VALUE!
